<mujoco model="manipulator">
    <compiler angle="radian" meshdir="/home/erm/rl-project/meshes/" />
    <size njmax="500" nconmax="100" />
    <asset>
        <mesh name="base_link" file="base_link.STL" />
        <mesh name="link_1" file="link_1.STL" />
        <mesh name="link_2" file="link_2.STL" />
        <mesh name="link_3" file="link_3.STL" />
    </asset>
    <worldbody>
    	<geom name="ground" type="plane" pos="0 0 0" size="2 2 0.1" rgba="0.6 0.8 1 1" friction="1 0.005 0.0001" />
    	<light name="ambient_light" pos="0 0 2" dir="0 0 -1" diffuse="0.2 0.2 0.2" specular="0.1 0.1 0.1" ambient="0.2 0.2 0.2" directional="true" />
    
        <geom type="mesh" contype="0" conaffinity="0" group="1" rgba="0.25098 0.25098 0.25098 1" mesh="base_link" />
        <geom type="mesh" rgba="0.25098 0.25098 0.25098 1" mesh="base_link" />
        <body name="link_1" pos="0 0 0.158">
            <inertial pos="0.033215 -0.0082402 0.12846" quat="0.899131 0.0812666 -0.353255 -0.245295" mass="5.7854" diaginertia="0.0457732 0.038138 0.0238257" />
            <joint name="link_1_joint" pos="0 0 0" axis="0 0 1" />
            <geom type="mesh" contype="0" conaffinity="0" group="1" rgba="1 1 1 1" mesh="link_1" />
            <geom type="mesh" rgba="1 1 1 1" mesh="link_1" />
            <body name="link_2" pos="0.062468 0.11617 0.18">
                <inertial pos="0.021249 0.0010698 0.16335" quat="0.731774 -0.00441777 -0.00264645 0.681527" mass="6.2559" diaginertia="0.146809 0.141204 0.0152276" />
                <joint name="link_2_joint" pos="0 0 0" axis="0 1 0" limited="true" range="-2 2" />
                <geom type="mesh" contype="0" conaffinity="0" group="1" rgba="1 1 1 1" mesh="link_2" />
                <geom type="mesh" rgba="1 1 1 1" mesh="link_2" />
                <body name="link_3" pos="0.012532 -0.11717 0.365">
                    <inertial pos="-0.062257 -0.0012327 0.14769" quat="0.548153 0.0890732 0.0521709 0.829984" mass="7.1667" diaginertia="0.164013 0.160813 0.0216148" />
                    <joint name="link_3_joint" pos="0 0 0" axis="0 1 0" limited="true" range="-2 2" />
                    <geom type="mesh" contype="0" conaffinity="0" group="1" rgba="1 1 1 1" mesh="link_3" />
                    <geom type="mesh" rgba="1 1 1 1" mesh="link_3" />
                    <body name="end_effector" pos="-0.090 0 0.48">
        		<geom type="cylinder" size="0.01 0.02" rgba="0 1 0 1" />
    		    </body>
                </body>
            </body>
        </body>
        <!-- Target -->
        <body name="target" pos="0 0 0.01">
            <geom conaffinity="0" contype="0" name="target" pos="0 0 0" rgba="0.9 0.2 0.2 1" size="0.02" type="sphere"/>
        </body>
    </worldbody>
    <actuator>
    	<motor joint="link_1_joint" ctrllimited="true" ctrlrange="-10.0 10.0" gear="100.0" />
    	<motor joint="link_2_joint" ctrllimited="true" ctrlrange="-10.0 10.0" gear="30.0" />
    	<motor joint="link_3_joint" ctrllimited="true" ctrlrange="-10.0 10.0" gear="10.0" />
    </actuator>

</mujoco>
